<?xml version="1.0" encoding="utf-8"?>
<!-- This URDF was automatically created by SolidWorks to URDF Exporter! Originally created by Stephen Brawner (brawner@gmail.com) 
     Commit Version: 1.6.0-4-g7f85cfe  Build Version: 1.6.7995.38578
     For more information, please see http://wiki.ros.org/sw_urdf_exporter -->
<robot
  name="snot_bot">
  <link
    name="base_link">
    <visual>
      <origin
        xyz="0 0 0"
        rpy="0 0 0" />
      <geometry>
        <mesh
          filename="package://snot_robot_description/meshes/base_link.STL" />
      </geometry>
      <material
        name="">
        <color
          rgba="0.79216 0.81961 0.93333 1" />
      </material>
    </visual>
    <collision>
      <origin
        xyz="0 0 0"
        rpy="0 0 0" />
      <geometry>
        <mesh
          filename="package://snot_robot_description/meshes/base_link.STL" />
      </geometry>
    </collision>
  </link>
  <link
  
    name="left_front_wheel">
    <inertial>
      <origin
        xyz="0 -0.0185 2.1684E-19"
        rpy="0 0 0" />
      <mass
        value="0.18412" />
      <inertia
        ixx="9.5391E-05"
        ixy="-6.5292E-23"
        ixz="1.6664E-21"
        iyy="0.00014877"
        iyz="2.4485E-23"
        izz="9.5391E-05" />
    </inertial>
    <visual>
      <origin
        xyz="0 0 0"
        rpy="0 0 0" />
      <geometry>
        <mesh
          filename="package://snot_robot_description/meshes/left_front_wheel.STL" />
      </geometry>
      <material
        name="">
        <color
          rgba="0.79216 0.81961 0.93333 1" />
      </material>
    </visual>
    <collision>
      <origin
        xyz="0 0 0"
        rpy="0 0 0" />
      <geometry>
        <mesh
          filename="package://snot_robot_description/meshes/left_front_wheel.STL" />
      </geometry>
    </collision>
  </link>
  <joint
    name="left_front_wheel"
    type="continuous">
    <origin
      xyz="0.12982 0.229 0.039505"
      rpy="0 0 0" />
    <parent
      link="base_link" />
    <child
      link="left_front_wheel" />
    <axis
      xyz="0 1 0" />
  </joint>
  <link
    name="left_rear_wheel">
    <inertial>
      <origin
        xyz="6.9389E-18 -0.0185 -1.5179E-18"
        rpy="0 0 0" />
      <mass
        value="0.18412" />
      <inertia
        ixx="9.5391E-05"
        ixy="6.5292E-23"
        ixz="1.9598E-21"
        iyy="0.00014877"
        iyz="6.6753E-21"
        izz="9.5391E-05" />
    </inertial>
    <visual>
      <origin
        xyz="0 0 0"
        rpy="0 0 0" />
      <geometry>
        <mesh
          filename="package://snot_robot_description/meshes/left_rear_wheel.STL" />
      </geometry>
      <material
        name="">
        <color
          rgba="0.79216 0.81961 0.93333 1" />
      </material>
    </visual>
    <collision>
      <origin
        xyz="0 0 0"
        rpy="0 0 0" />
      <geometry>
        <mesh
          filename="package://snot_robot_description/meshes/left_rear_wheel.STL" />
      </geometry>
    </collision>
  </link>
  <joint
    name="left_rear_wheel"
    type="continuous">
    <origin
      xyz="-0.12983 0.229 0.039505"
      rpy="0 0 0" />
    <parent
      link="base_link" />
    <child
      link="left_rear_wheel" />
    <axis
      xyz="0 1 0" />
  </joint>
  <link
    name="right_rear_wheel">
    <inertial>
      <origin
        xyz="3.4694E-18 0.0185 2.6021E-18"
        rpy="0 0 0" />
      <mass
        value="0.18412" />
      <inertia
        ixx="9.5391E-05"
        ixy="-2.122E-21"
        ixz="1.2911E-22"
        iyy="0.00014877"
        iyz="6.5356E-21"
        izz="9.5391E-05" />
    </inertial>
    <visual>
      <origin
        xyz="0 0 0"
        rpy="0 0 0" />
      <geometry>
        <mesh
          filename="package://snot_robot_description/meshes/right_rear_wheel.STL" />
      </geometry>
      <material
        name="">
        <color
          rgba="0.79216 0.81961 0.93333 1" />
      </material>
    </visual>
    <collision>
      <origin
        xyz="0 0 0"
        rpy="0 0 0" />
      <geometry>
        <mesh
          filename="package://snot_robot_description/meshes/right_rear_wheel.STL" />
      </geometry>
    </collision>
  </link>
  <joint
    name="right_rear_wheel"
    type="continuous">
    <origin
      xyz="-0.12983 -0.229 0.039505"
      rpy="0 0 0" />
    <parent
      link="base_link" />
    <child
      link="right_rear_wheel" />
    <axis
      xyz="0 1 0" />
  </joint>
  <link
    name="right_front_wheel">
    <inertial>
      <origin
        xyz="0 0.0185 2.3852E-18"
        rpy="0 0 0" />
      <mass
        value="0.18412" />
      <inertia
        ixx="9.5391E-05"
        ixy="-2.0893E-21"
        ixz="-2.6085E-37"
        iyy="0.00014877"
        iyz="6.6672E-21"
        izz="9.5391E-05" />
    </inertial>
    <visual>
      <origin
        xyz="0 0 0"
        rpy="0 0 0" />
      <geometry>
        <mesh
          filename="package://snot_robot_description/meshes/right_front_wheel.STL" />
      </geometry>
      <material
        name="">
        <color
          rgba="0.79216 0.81961 0.93333 1" />
      </material>
    </visual>
    <collision>
      <origin
        xyz="0 0 0"
        rpy="0 0 0" />
      <geometry>
        <mesh
          filename="package://snot_robot_description/meshes/right_front_wheel.STL" />
      </geometry>
    </collision>
  </link>
  <joint
    name="right_front_wheel"
    type="continuous">
    <origin
      xyz="0.12982 -0.229 0.039505"
      rpy="0 0 0" />
    <parent
      link="base_link" />
    <child
      link="right_front_wheel" />
    <axis
      xyz="0 1 0" />
  </joint>
  <link
    name="camera">
    <inertial>
      <origin
        xyz="0.00047839 0.016521 -0.029048"
        rpy="0 0 0" />
      <mass
        value="0.82085" />
      <inertia
        ixx="0.00040911"
        ixy="5.4099E-06"
        ixz="1.8347E-05"
        iyy="0.0039182"
        iyz="-3.0404E-05"
        izz="0.0037595" />
    </inertial>
    <visual>
      <origin
        xyz="0 0 0"
        rpy="0 0 0" />
      <geometry>
        <mesh
          filename="package://snot_robot_description/meshes/camera.STL" />
      </geometry>
      <material
        name="">
        <color
          rgba="0.75294 0.75294 0.75294 1" />
      </material>
    </visual>
    <collision>
      <origin
        xyz="0 0 0"
        rpy="0 0 0" />
      <geometry>
        <mesh
          filename="package://snot_robot_description/meshes/camera.STL" />
      </geometry>
    </collision>
  </link>
  <joint
    name="camera"
    type="fixed">
    <origin
      xyz="0.143 0 0.10243"
      rpy="1.5708 0 1.5708" />
    <parent
      link="base_link" />
    <child
      link="camera" />
    <axis
      xyz="0 0 0" />
  </joint>
  <link
    name="lidar">
    <inertial>
      <origin
        xyz="0.0063461 -9.1926E-05 -0.022432"
        rpy="0 0 0" />
      <mass
        value="1.3308" />
      <inertia
        ixx="0.00061492"
        ixy="-8.0198E-07"
        ixz="0.00015824"
        iyy="0.0009607"
        iyz="-3.0916E-06"
        izz="0.0010982" />
    </inertial>
    <visual>
      <origin
        xyz="0 0 0"
        rpy="0 0 0" />
      <geometry>
        <mesh
          filename="package://snot_robot_description/meshes/lidar.STL" />
      </geometry>
      <material
        name="">
        <color
          rgba="0.25098 0.25098 0.25098 1" />
      </material>
    </visual>
    <collision>
      <origin
        xyz="0 0 0"
        rpy="0 0 0" />
      <geometry>
        <mesh
          filename="package://snot_robot_description/meshes/lidar.STL" />
      </geometry>
    </collision>
  </link>
  <joint
    name="lidar"
    type="fixed">
    <origin
      xyz="-0.00042039 0 0.22613"
      rpy="0 0 3.1416" />
    <parent
      link="base_link" />
    <child
      link="lidar" />
    <axis
      xyz="0 0 0" />
  </joint>
</robot>